Traceback (most recent call last):
  File "C:\Users\loren\miniconda3\envs\venv_py\lib\site-packages\jupyter_cache\executors\utils.py", line 58, in single_nb_execution
    executenb(
  File "C:\Users\loren\miniconda3\envs\venv_py\lib\site-packages\nbclient\client.py", line 1314, in execute
    return NotebookClient(nb=nb, resources=resources, km=km, **kwargs).execute()
  File "C:\Users\loren\miniconda3\envs\venv_py\lib\site-packages\jupyter_core\utils\__init__.py", line 165, in wrapped
    return loop.run_until_complete(inner)
  File "C:\Users\loren\miniconda3\envs\venv_py\lib\asyncio\base_events.py", line 647, in run_until_complete
    return future.result()
  File "C:\Users\loren\miniconda3\envs\venv_py\lib\site-packages\nbclient\client.py", line 709, in async_execute
    await self.async_execute_cell(
  File "C:\Users\loren\miniconda3\envs\venv_py\lib\site-packages\nbclient\client.py", line 1062, in async_execute_cell
    await self._check_raise_for_error(cell, cell_index, exec_reply)
  File "C:\Users\loren\miniconda3\envs\venv_py\lib\site-packages\nbclient\client.py", line 918, in _check_raise_for_error
    raise CellExecutionError.from_cell_and_msg(cell, exec_reply_content)
nbclient.exceptions.CellExecutionError: An error occurred while executing the following cell:
------------------
test32_data = pd.read_feather('/content/drive/My Drive/test_data_jq_f32.ftr')

print(test32_data.head())
------------------


[1;31m---------------------------------------------------------------------------[0m
[1;31mFileNotFoundError[0m                         Traceback (most recent call last)
Cell [1;32mIn[2], line 1[0m
[1;32m----> 1[0m test32_data [38;5;241m=[39m [43mpd[49m[38;5;241;43m.[39;49m[43mread_feather[49m[43m([49m[38;5;124;43m'[39;49m[38;5;124;43m/content/drive/My Drive/test_data_jq_f32.ftr[39;49m[38;5;124;43m'[39;49m[43m)[49m
[0;32m      3[0m [38;5;28mprint[39m(test32_data[38;5;241m.[39mhead())

File [1;32m~\miniconda3\envs\venv_py\lib\site-packages\pandas\io\feather_format.py:122[0m, in [0;36mread_feather[1;34m(path, columns, use_threads, storage_options, dtype_backend)[0m
[0;32m    118[0m [38;5;28;01mfrom[39;00m [38;5;21;01mpyarrow[39;00m [38;5;28;01mimport[39;00m feather
[0;32m    120[0m check_dtype_backend(dtype_backend)
[1;32m--> 122[0m [38;5;28;01mwith[39;00m [43mget_handle[49m[43m([49m
[0;32m    123[0m [43m    [49m[43mpath[49m[43m,[49m[43m [49m[38;5;124;43m"[39;49m[38;5;124;43mrb[39;49m[38;5;124;43m"[39;49m[43m,[49m[43m [49m[43mstorage_options[49m[38;5;241;43m=[39;49m[43mstorage_options[49m[43m,[49m[43m [49m[43mis_text[49m[38;5;241;43m=[39;49m[38;5;28;43;01mFalse[39;49;00m
[0;32m    124[0m [43m[49m[43m)[49m [38;5;28;01mas[39;00m handles:
[0;32m    125[0m     [38;5;28;01mif[39;00m dtype_backend [38;5;129;01mis[39;00m lib[38;5;241m.[39mno_default [38;5;129;01mand[39;00m [38;5;129;01mnot[39;00m using_pyarrow_string_dtype():
[0;32m    126[0m         [38;5;28;01mreturn[39;00m feather[38;5;241m.[39mread_feather(
[0;32m    127[0m             handles[38;5;241m.[39mhandle, columns[38;5;241m=[39mcolumns, use_threads[38;5;241m=[39m[38;5;28mbool[39m(use_threads)
[0;32m    128[0m         )

File [1;32m~\miniconda3\envs\venv_py\lib\site-packages\pandas\io\common.py:872[0m, in [0;36mget_handle[1;34m(path_or_buf, mode, encoding, compression, memory_map, is_text, errors, storage_options)[0m
[0;32m    863[0m         handle [38;5;241m=[39m [38;5;28mopen[39m(
[0;32m    864[0m             handle,
[0;32m    865[0m             ioargs[38;5;241m.[39mmode,
[1;32m   (...)[0m
[0;32m    868[0m             newline[38;5;241m=[39m[38;5;124m"[39m[38;5;124m"[39m,
[0;32m    869[0m         )
[0;32m    870[0m     [38;5;28;01melse[39;00m:
[0;32m    871[0m         [38;5;66;03m# Binary mode[39;00m
[1;32m--> 872[0m         handle [38;5;241m=[39m [38;5;28;43mopen[39;49m[43m([49m[43mhandle[49m[43m,[49m[43m [49m[43mioargs[49m[38;5;241;43m.[39;49m[43mmode[49m[43m)[49m
[0;32m    873[0m     handles[38;5;241m.[39mappend(handle)
[0;32m    875[0m [38;5;66;03m# Convert BytesIO or file objects passed with an encoding[39;00m

[1;31mFileNotFoundError[0m: [Errno 2] No such file or directory: '/content/drive/My Drive/test_data_jq_f32.ftr'

