Traceback (most recent call last):
  File "C:\Users\loren\miniconda3\envs\venv_py\lib\site-packages\jupyter_cache\executors\utils.py", line 58, in single_nb_execution
    executenb(
  File "C:\Users\loren\miniconda3\envs\venv_py\lib\site-packages\nbclient\client.py", line 1314, in execute
    return NotebookClient(nb=nb, resources=resources, km=km, **kwargs).execute()
  File "C:\Users\loren\miniconda3\envs\venv_py\lib\site-packages\jupyter_core\utils\__init__.py", line 165, in wrapped
    return loop.run_until_complete(inner)
  File "C:\Users\loren\miniconda3\envs\venv_py\lib\asyncio\base_events.py", line 647, in run_until_complete
    return future.result()
  File "C:\Users\loren\miniconda3\envs\venv_py\lib\site-packages\nbclient\client.py", line 709, in async_execute
    await self.async_execute_cell(
  File "C:\Users\loren\miniconda3\envs\venv_py\lib\site-packages\nbclient\client.py", line 1062, in async_execute_cell
    await self._check_raise_for_error(cell, cell_index, exec_reply)
  File "C:\Users\loren\miniconda3\envs\venv_py\lib\site-packages\nbclient\client.py", line 918, in _check_raise_for_error
    raise CellExecutionError.from_cell_and_msg(cell, exec_reply_content)
nbclient.exceptions.CellExecutionError: An error occurred while executing the following cell:
------------------
# Unir los DataFrames usando 'customer_ID'
df_data = pd.merge(tra_label, tra_data, on='customer_ID', how='outer')

print(df_data.head())

------------------


[1;31m---------------------------------------------------------------------------[0m
[1;31mNameError[0m                                 Traceback (most recent call last)
Cell [1;32mIn[6], line 2[0m
[0;32m      1[0m [38;5;66;03m# Unir los DataFrames usando 'customer_ID'[39;00m
[1;32m----> 2[0m df_data [38;5;241m=[39m pd[38;5;241m.[39mmerge([43mtra_label[49m, tra_data, on[38;5;241m=[39m[38;5;124m'[39m[38;5;124mcustomer_ID[39m[38;5;124m'[39m, how[38;5;241m=[39m[38;5;124m'[39m[38;5;124mouter[39m[38;5;124m'[39m)
[0;32m      4[0m [38;5;28mprint[39m(df_data[38;5;241m.[39mhead())

[1;31mNameError[0m: name 'tra_label' is not defined

